Workbook

Sheet Sample
A1: Estimate of Ramfal Building
A2: Sr No | B2: HSR Item No | C2: Description | D2: Nos | E2: Length | F2: Breadth | G2: Depth | H2: Quantity | I2: Unit | J2: Rate Type | K2: Rate | L2: Amount
A3: =IFERROR(LOOKUP(2,1/(ISNUMBER($A$2:$A$2)),$A$2:$A$2),0)+1 -> 1 | B3: 4.14.1 | C3: 4.14: Earth Work and Rock Cutting Earth work in excavation by mechanical means (Hydraulic excavator) / manual means in foundation trenches or drains (not exceeding 1.5 m in width or 10 sqm on plan), including dressing of sides and ramming of bottoms, lift up to 1.5 m, including getting out the excavated soil and disposal of surplus excavated soil as directed, within a lead of 50 m. 4.14.1: All kinds of soil.
C4: Side wall | D4: 2 | E4: 71.625 | F4: 3 | G4: 3 | H4: =D4*IF(OR(E4=0,E4="-"),1,E4)*IF(OR(F4=0,F4="-"),1,F4)*IF(OR(G4=0,G4="-"),1,G4) -> 1289.25 | I4: cft
C5: Toe wall | D5: 3 | E5: 33.375 | F5: 3 | G5: 3 | H5: =D5*IF(OR(E5=0,E5="-"),1,E5)*IF(OR(F5=0,F5="-"),1,F5)*IF(OR(G5=0,G5="-"),1,G5) -> 901.125 | I5: cft
F6: Total (cft) | H6: =SUM(H4:INDEX(H:H,ROW()-1)) -> 2190.375 | I6: cft | K6: =0 -> 0
E7: Total (cum) | H7: =ROUND(H6*0.028316846592,3) -> 62.025 | I7: cum | J7: Through Rate | K7: =IF(B3="4.14.1",IF(J7="Labour Rate",20,IF(J7="Machinery Rate",63,IF(J7="Through Rate",83,0))),"") -> 83 | L7: =IF(H7*K7<>0,H7*K7,0) -> 5148.075
A9: =IFERROR(LOOKUP(2,1/(ISNUMBER($A$2:$A$8)),$A$2:$A$8),0)+1 -> 2 | B9: RM079 | C9: RM079: Earth Cost or compensation for earth taken from private land
D10: 1 | E10: 150 | F10: 1 | G10: 1 | H10: =D10*IF(OR(E10=0,E10="-"),1,E10)*IF(OR(F10=0,F10="-"),1,F10)*IF(OR(G10=0,G10="-"),1,G10) -> 150 | I10: cft
F11: Total (cft) | H11: =SUM(H10:INDEX(H:H,ROW()-1)) -> 150 | I11: cft | K11: =0 -> 0
E12: Total (cum) | H12: =ROUND(H11*0.028316846592,3) -> 4.248 | I12: cum | J12: Rate | K12: =IF(B9="RM079",IF(J12="Rate",18,0),"") -> 18 | L12: =IF(H12*K12<>0,H12*K12,0) -> 76.464
A14: =IFERROR(LOOKUP(2,1/(ISNUMBER($A$2:$A$13)),$A$2:$A$13),0)+1 -> 3 | B14: 3.1.2 | C14: 3.1: Loading, Unloading and Carriage of Materials Schedule A By Mechanical Transport including loading, unloading and stacking 3.1.2: Earth
C15: 5KM | D15: 1 | E15: 150 | F15: 1 | G15: 1 | H15: =D15*IF(OR(E15=0,E15="-"),1,E15)*IF(OR(F15=0,F15="-"),1,F15)*IF(OR(G15=0,G15="-"),1,G15) -> 150 | I15: cft
F16: Total (cft) | H16: =SUM(H15:INDEX(H:H,ROW()-1)) -> 150 | I16: cft | K16: =0 -> 0
E17: Total (cum) | H17: =ROUND(H16*0.028316846592,3) -> 4.248 | I17: cum | J17: 5km | K17: =IF(B14="3.1.2",IF(J17="1km",53,IF(J17="2km",60,IF(J17="3km",68,IF(J17="4km",75,IF(J17="5km",83,IF(J17="Beyond 5km up to 10km per KM",6,IF(J17="Beyond 10km up to 20km per KM",5,IF(J17="Beyond 20km per adl. KM",4,0)))))))),"") -> 83 | L17: =IF(H17*K17<>0,H17*K17,0) -> 352.584
A19: =IFERROR(LOOKUP(2,1/(ISNUMBER($A$2:$A$18)),$A$2:$A$18),0)+1 -> 4 | B19: 3.1.2 | C19: 3.1: Loading, Unloading and Carriage of Materials Schedule A By Mechanical Transport including loading, unloading and stacking 3.1.2: Earth
C20: 6km - 8km | D20: 3 | E20: 150 | F20: 1 | G20: 1 | H20: =D20*IF(OR(E20=0,E20="-"),1,E20)*IF(OR(F20=0,F20="-"),1,F20)*IF(OR(G20=0,G20="-"),1,G20) -> 450 | I20: cft
F21: Total (cft) | H21: =SUM(H20:INDEX(H:H,ROW()-1)) -> 450 | I21: cft | K21: =0 -> 0
E22: Total (cum) | H22: =ROUND(H21*0.028316846592,3) -> 12.743 | I22: cum | J22: Beyond 5km up to 10km per KM | K22: =IF(B19="3.1.2",IF(J22="1km",53,IF(J22="2km",60,IF(J22="3km",68,IF(J22="4km",75,IF(J22="5km",83,IF(J22="Beyond 5km up to 10km per KM",6,IF(J22="Beyond 10km up to 20km per KM",5,IF(J22="Beyond 20km per adl. KM",4,0)))))))),"") -> 6 | L22: =IF(H22*K22<>0,H22*K22,0) -> 76.458
A24: =IFERROR(LOOKUP(2,1/(ISNUMBER($A$2:$A$23)),$A$2:$A$23),0)+1 -> 5 | B24: CA044 | C24: CA044: Spun iron S & S pipes 125 mm dia
C25: Columns | D25: 12 | E25: 1.5 | H25: =D25*IF(OR(E25=0,E25="-"),1,E25)*IF(OR(F25=0,F25="-"),1,F25)*IF(OR(G25=0,G25="-"),1,G25) -> 18 | I25: meter
C26: Toe wall | D26: 1 | E26: 236 | H26: =D26*IF(OR(E26=0,E26="-"),1,E26)*IF(OR(F26=0,F26="-"),1,F26)*IF(OR(G26=0,G26="-"),1,G26) -> 236 | I26: meter
D27: 1 | E27: 38.125 | H27: =D27*IF(OR(E27=0,E27="-"),1,E27)*IF(OR(F27=0,F27="-"),1,F27)*IF(OR(G27=0,G27="-"),1,G27) -> 38.125 | I27: meter
D28: 1 | E28: 39.125 | H28: =D28*IF(OR(E28=0,E28="-"),1,E28)*IF(OR(F28=0,F28="-"),1,F28)*IF(OR(G28=0,G28="-"),1,G28) -> 39.125 | I28: meter
F29: Total (meter) | H29: =SUM(H25:INDEX(H:H,ROW()-1)) -> 331.25 | I29: meter
E30: Total (meter) | H30: =ROUND(H29*1,3) -> 331.25 | I30: meter
E31: Total (Per 100 meters) | H31: =H30/100 -> 3.3125 | I31: 100 meters | J31: Rate | K31: =IF(B24="CA044",IF(J31="Rate",289,0),"") -> 289 | L31: =IF(H31*K31<>0,H31*K31,0) -> 957.3125
A33: =IFERROR(LOOKUP(2,1/(ISNUMBER($A$2:$A$32)),$A$2:$A$32),0)+1 -> 6 | B33: 6.34.6 | C33: 6.34: Steel reinforcement for R.C.C. work, where not included in the complete rate of RCC, including straightening, cutting, bending, placing in position, binding, wastage, overlaps, welded joints, spacer bars, chairs, stays, hangers and annealed steel wire etc. complete in all respect above plinth level. Note:- Reinforcement shall be measured in length including hooks, if any, separately for different diameters as actually used in work , excluding overlaps. Wastage, overlaps, couplings, welded joints, spacer bars, chairs, stays, hangers and annealed steel wire or other methods of binding & placing shall not be measured and cost of these items shall be deemed to be included in the rates for reinforcement. 6.34.6: Thermo-Mechanically Treated bars of grade Fe-500D or more.
C34: steel weight | D34: 1 | E34: 40 | H34: =D34*IF(OR(E34=0,E34="-"),1,E34)*IF(OR(F34=0,F34="-"),1,F34)*IF(OR(G34=0,G34="-"),1,G34) -> 40 | I34: kg
F35: Total (kg) | H35: =SUM(H34:INDEX(H:H,ROW()-1)) -> 40 | I35: kg | K35: =0 -> 0
E36: Total (kg) | H36: =ROUND(H35*1,3) -> 40 | I36: kg | J36: Through Rate Amnd | K36: =IF(B33="6.34.6",IF(J36="Labour Rate",2,IF(J36="Material Rate",59,IF(J36="Through Rate",61,IF(J36="Labour Rate Amnd",6,IF(J36="Material Rate Amnd",62,IF(J36="Through Rate Amnd",68,0)))))),"") -> 68 | L36: =IF(H36*K36<>0,H36*K36,0) -> 2720
A38: =IFERROR(LOOKUP(2,1/(ISNUMBER($A$2:$A$37)),$A$2:$A$37),0)+1 -> 7 | B38: 6.33.6 | C38: 6.33: Steel reinforcement for R.C.C. work, where not included in the complete rate of RCC, including straightening, cutting, bending, placing in position, binding, wastage, overlaps, welded joints, spacer bars, chairs, stays, hangers and annealed steel wire etc. complete in all respect for all heights/depths/storeys/basements etc. complete in all respect below plinth level. Note: - Reinforcement shall be measured in length including hooks, if any, separately for different diameters as actually used in work, excluding overlaps. Wastage, overlaps, couplings, welded joints, spacer bars, chairs, stays, hangers and annealed steel wire or other methods of binding and placing shall not be measured and cost of these items shall be deemed to be included in the rates for reinforcement. 6.33.6: Thermo-Mechanically Treated bars of grade Fe-500D or more.
C39: Thermo-Mechanically Treated bars of grade Fe-500D kg or more.
C40: 12mm dia
D41: 10 | E41: 4 | F41: 6 | H41: =D41*IF(OR(E41=0,E41="-"),1,E41)*IF(OR(F41=0,F41="-"),1,F41)*IF(OR(G41=0,G41="-"),1,G41) -> 240 | I41: rft
F42: Total (rft) | H42: =SUM(H41:INDEX(H:H,ROW()-1)) -> 240 | I42: rft
E43: Total (meter) | H43: =ROUND(H42*0.3048,3) -> 73.152 | I43: meter
E44: Total (Weight of φ12mm Rebar) | H44: =(H43*12^2)/162 -> 65.024 | I44: Kg | J44: A
C46: 8mm dia
C47: Ring (15*15) | D47: 120 | E47: 5.4166667 | H47: =D47*IF(OR(E47=0,E47="-"),1,E47)*IF(OR(F47=0,F47="-"),1,F47)*IF(OR(G47=0,G47="-"),1,G47) -> 650 | I47: rft
...

Sheet ABSTRACT BILL
A1: Abstract Summary of: Sample
A2: Sr. | B2: Item No | C2: Description | D2: Qty | E2: Unit | F2: Rate | G2: Amount
A3: =Sample!A3 -> 1 | B3: 4.14.1 | C3: 4.14: Earth Work and Rock Cutting Earth work in excavation by mechanical means (Hydraulic excavator) / manual means in foundation trenches or drains (not exceeding 1.5 m in width or 10 sqm on plan), including dressing of sides and ramming of bottoms, lift up to 1.5 m, including getting out the excavated soil and disposal of surplus excavated soil as directed, within a lead of 50 m. 4.14.1: All kinds of soil. (Through Rate) | D3: =Sample!H7 -> 62.025 | E3: cum | F3: =Sample!K7 -> 83 | G3: =D3*F3 -> 5148.075
A4: =Sample!A9 -> 2 | B4: RM079 | C4: RM079: Earth Cost or compensation for earth taken from private land (Rate) | D4: =Sample!H12 -> 4.248 | E4: cum | F4: =Sample!K12 -> 18 | G4: =D4*F4 -> 76.464
A5: =Sample!A14 -> 3 | B5: 3.1.2 | C5: 3.1: Loading, Unloading and Carriage of Materials Schedule A By Mechanical Transport including loading, unloading and stacking 3.1.2: Earth (5km) | D5: =Sample!H17 -> 4.248 | E5: cum | F5: =Sample!K17 -> 83 | G5: =D5*F5 -> 352.584
A6: =Sample!A19 -> 4 | B6: 3.1.2 | C6: 3.1: Loading, Unloading and Carriage of Materials Schedule A By Mechanical Transport including loading, unloading and stacking 3.1.2: Earth (Beyond 5km up to 10km per KM) | D6: =Sample!H22 -> 12.743 | E6: cum | F6: =Sample!K22 -> 6 | G6: =D6*F6 -> 76.458
A7: =Sample!A24 -> 5 | B7: CA044 | C7: CA044: Spun iron S & S pipes 125 mm dia (Rate) | D7: =Sample!H31 -> 3.3125 | E7: 100 meters | F7: =Sample!K31 -> 289 | G7: =D7*F7 -> 957.3125
A8: =Sample!A33 -> 6 | B8: 6.34.6 | C8: 6.34: Steel reinforcement for R.C.C. work, where not included in the complete rate of RCC, including straightening, cutting, bending, placing in position, binding, wastage, overlaps, welded joints, spacer bars, chairs, stays, hangers and annealed steel wire etc. complete in all respect above plinth level. Note:- Reinforcement shall be measured in length including hooks, if any, separately for different diameters as actually used in work , excluding overlaps. Wastage, overlaps, couplings, welded joints, spacer bars, chairs, stays, hangers and annealed steel wire or other methods of binding & placing shall not be measured and cost of these items shall be deemed to be included in the rates for reinforcement. 6.34.6: Thermo-Mechanically Treated bars of grade Fe-500D or more. (Through Rate Amnd) | D8: =Sample!H36 -> 40 | E8: kg | F8: =Sample!K36 -> 68 | G8: =D8*F8 -> 2720
A9: =Sample!A38 -> 7 | B9: 6.33.6 | C9: 6.33: Steel reinforcement for R.C.C. work, where not included in the complete rate of RCC, including straightening, cutting, bending, placing in position, binding, wastage, overlaps, welded joints, spacer bars, chairs, stays, hangers and annealed steel wire etc. complete in all respect for all heights/depths/storeys/basements etc. complete in all respect below plinth level. Note: - Reinforcement shall be measured in length including hooks, if any, separately for different diameters as actually used in work, excluding overlaps. Wastage, overlaps, couplings, welded joints, spacer bars, chairs, stays, hangers and annealed steel wire or other methods of binding and placing shall not be measured and cost of these items shall be deemed to be included in the rates for reinforcement. 6.33.6: Thermo-Mechanically Treated bars of grade Fe-500D or more. (Through Rate Amnd) | D9: =Sample!H52 -> 143.294 | E9: kg | F9: =Sample!K52 -> 66 | G9: =D9*F9 -> 9457.404
A10: =Sample!A54 -> 8 | B10: 13.31 | C10: 13.31: Steel and Iron Work SIGLE/BUILT-UP STEEL/TUBULAR SECTIONS Providing and fixing mild steel round holding down bolts with nuts and washer plates complete. (Through Rate) | D10: =Sample!H62 -> 50.998 | E10: kg | F10: =Sample!K62 -> 66 | G10: =D10*F10 -> 3365.868
A11: =Sample!A64 -> 9 | B11: 13.30.1 | C11: 13.30: Steel and Iron Work SIGLE/BUILT-UP STEEL/TUBULAR SECTIONS Steel work in built up tubular (round, square or rectangular hollow tubes etc.) trusses etc., including cutting, hoisting, fixing in position and applying a priming coat of approved steel primer, including welding and bolted with special shaped washers etc. complete. 13.30.1: Hot finished welded type tubes (Through Rate) | D11: =Sample!H83 -> 2167.833 | E11: kg | F11: =Sample!K83 -> 105 | G11: =D11*F11 -> 227622.46
A12: =Sample!A85 -> 10 | B12: 7.22.2 | C12: 7.22: Brick work with common burnt clay non- modular bricks of class designation 7.5 in superstructure above plinth level up to floor IV level in all shapes and sizes in : 7.22.2: Cement mortar 1:6 (1 cement : 6 coarse sand) (Through Rate Amnd) | D12: =Sample!H93 -> 6.578 | E12: cum | F12: =Sample!K93 -> 4488 | G12: =D12*F12 -> 29522.064
A13: =Sample!A95 -> 11 | B13: 9.59.2 | C13: 9.59: Hoisting and Roofing RAIN WATER SPOUTS AND PIPES Providing and fixing Unplasticised -PVC pipe clips of approved design to Unplasticised - PVC rain water pipes by means of 50x50x50 mm hard wood plugs, screwed with M.S. screws of required length, including cutting brick work and fixing in cement mortar 1:4 (1 cement : 4 coarse sand) and making good the wall etc. complete. 9.59.2: 110 mm (Through Rate) | D13: =Sample!H98 -> 1 | E13: each | F13: =Sample!K98 -> 147 | G13: =D13*F13 -> 147
A14: =Sample!A100 -> 12 | B14: 22.181 | C14: 22.181: Sanitary Installations LOFT AND TERRACE WATER TANKS Providing and placing on terrace (at all floor levels) polyethylene water storage tank, IS : 12701 marked, with cover and suitable locking arrangement and making necessary holes for inlet, outlet and overflow pipes but without fittings and the base support for tank. (Through Rate) | D14: =Sample!H103 -> 500 | E14: litre | F14: =Sample!K103 -> 7 | G14: =D14*F14 -> 3500
A15: =Sample!A105 -> 13 | B15: 22.222.2.2 | C15: 22.222: Sanitary Installations HDPE pipes for Drainage Providing and fixing in position singel socket SWR UPVC soil waste or antisyphonage pipes as per IS 13592 of E.D.C manufacture or of any other reputed firm including cutting, jointing, wastage, but excluding cost of jointing. 22.222.2.2: Single Socket Type B 110mm o/d SWR UPVC pipe lines laid complete (Through Rate) | D15: =Sample!H108 -> 40 | E15: meter | F15: =Sample!K108 -> 322 | G15: =D15*F15 -> 12880
A16: =Sample!A110 -> 14 | B16: NS - Pan | C16: manual description(NS) | D16: =Sample!H113 -> 10 | F16: =Sample!K113 -> 5 | G16: =D16*F16 -> 50
A17: Total | D17: =SUBTOTAL(109,SummaryTable_20260610_172630[Qty]) -> 3046.2795 | G17: =SUBTOTAL(109,SummaryTable_20260610_172630[Amount]) -> 295875.69

Sheet Steel Summary
A4: Steel Summary (Sample) | D4: Quantity (KG)
A5: Weight of φ12mm Rebar (Kg) | D5: =SUMIF(Sample!E2:E113,"Total (Weight of φ12mm Rebar)",Sample!H2:H113) -> 65.024
A6: Weight of φ8mm Rebar (Kg) | D6: =SUMIF(Sample!E2:E113,"Total (Weight of φ8mm Rebar)",Sample!H2:H113) -> 78.26963
A7: Weight for 32.4 Kg per Sqm (Kg) | D7: =SUMIF(Sample!E2:E113,"Total (Weight for 32.4 Kg per Sqm)",Sample!H2:H113) -> 50.9976
A8: Weight for 18.361 Kg per Meter (Kg) | D8: =SUMIF(Sample!E2:E113,"Total (Weight for 18.361 Kg per Meter)",Sample!H2:H113) -> 783.50059
A9: Weight for 6.8 Kg per Meter (Kg) | D9: =SUMIF(Sample!E2:E113,"Total (Weight for 6.8 Kg per Meter)",Sample!H2:H113) -> 671.534
A10: Weight for 7.21785 Kg per Meter (Kg) | D10: =SUMIF(Sample!E2:E113,"Total (Weight for 7.21785 Kg per Meter)",Sample!H2:H113) -> 712.79878
A11: Total | D11: =SUM($D$5:$D$10) -> 2362.1246
A13: steel weight | D13: 40
D14: =D13+D11 -> 2402.1246
